2017-11-29 16:14:03,743 - api - ERROR - Exception on /api/labs/week1 [GET]
Traceback (most recent call last):
  File "/Library/Frameworks/Python.framework/Versions/3.5/lib/python3.5/site-packages/flask/app.py", line 1988, in wsgi_app
    response = self.full_dispatch_request()
  File "/Library/Frameworks/Python.framework/Versions/3.5/lib/python3.5/site-packages/flask/app.py", line 1641, in full_dispatch_request
    rv = self.handle_user_exception(e)
  File "/Library/Frameworks/Python.framework/Versions/3.5/lib/python3.5/site-packages/flask/app.py", line 1544, in handle_user_exception
    reraise(exc_type, exc_value, tb)
  File "/Library/Frameworks/Python.framework/Versions/3.5/lib/python3.5/site-packages/flask/_compat.py", line 33, in reraise
    raise value
  File "/Library/Frameworks/Python.framework/Versions/3.5/lib/python3.5/site-packages/flask/app.py", line 1639, in full_dispatch_request
    rv = self.dispatch_request()
  File "/Library/Frameworks/Python.framework/Versions/3.5/lib/python3.5/site-packages/flask/app.py", line 1625, in dispatch_request
    return self.view_functions[rule.endpoint](**req.view_args)
  File "/Users/TheHD/Sites/teaching-api/api.py", line 51, in serveWeek
    'code': f.openFile(fp['path']),
  File "/Users/TheHD/Sites/teaching-api/model.py", line 22, in openFile
    return fo.read()
  File "/Library/Frameworks/Python.framework/Versions/3.5/lib/python3.5/encodings/ascii.py", line 26, in decode
    return codecs.ascii_decode(input, self.errors)[0]
UnicodeDecodeError: 'ascii' codec can't decode byte 0xe2 in position 579: ordinal not in range(128)
2017-11-29 16:21:28,252 - api - ERROR - Exception on /api/labs/week1 [GET]
Traceback (most recent call last):
  File "/Library/Frameworks/Python.framework/Versions/3.5/lib/python3.5/site-packages/flask/app.py", line 1988, in wsgi_app
    response = self.full_dispatch_request()
  File "/Library/Frameworks/Python.framework/Versions/3.5/lib/python3.5/site-packages/flask/app.py", line 1641, in full_dispatch_request
    rv = self.handle_user_exception(e)
  File "/Library/Frameworks/Python.framework/Versions/3.5/lib/python3.5/site-packages/flask/app.py", line 1544, in handle_user_exception
    reraise(exc_type, exc_value, tb)
  File "/Library/Frameworks/Python.framework/Versions/3.5/lib/python3.5/site-packages/flask/_compat.py", line 33, in reraise
    raise value
  File "/Library/Frameworks/Python.framework/Versions/3.5/lib/python3.5/site-packages/flask/app.py", line 1639, in full_dispatch_request
    rv = self.dispatch_request()
  File "/Library/Frameworks/Python.framework/Versions/3.5/lib/python3.5/site-packages/flask/app.py", line 1625, in dispatch_request
    return self.view_functions[rule.endpoint](**req.view_args)
  File "/Users/TheHD/Sites/teaching-api/api.py", line 44, in serveWeek
    'code': f.openFile(fp['path']),
  File "/Users/TheHD/Sites/teaching-api/model.py", line 22, in openFile
    return fo.read()
  File "/Library/Frameworks/Python.framework/Versions/3.5/lib/python3.5/encodings/ascii.py", line 26, in decode
    return codecs.ascii_decode(input, self.errors)[0]
UnicodeDecodeError: 'ascii' codec can't decode byte 0xe2 in position 579: ordinal not in range(128)
2017-11-29 16:25:00,089 - api - ERROR - Exception on /api/labs/week1 [GET]
Traceback (most recent call last):
  File "/Library/Frameworks/Python.framework/Versions/3.5/lib/python3.5/site-packages/flask/app.py", line 1988, in wsgi_app
    response = self.full_dispatch_request()
  File "/Library/Frameworks/Python.framework/Versions/3.5/lib/python3.5/site-packages/flask/app.py", line 1641, in full_dispatch_request
    rv = self.handle_user_exception(e)
  File "/Library/Frameworks/Python.framework/Versions/3.5/lib/python3.5/site-packages/flask/app.py", line 1544, in handle_user_exception
    reraise(exc_type, exc_value, tb)
  File "/Library/Frameworks/Python.framework/Versions/3.5/lib/python3.5/site-packages/flask/_compat.py", line 33, in reraise
    raise value
  File "/Library/Frameworks/Python.framework/Versions/3.5/lib/python3.5/site-packages/flask/app.py", line 1639, in full_dispatch_request
    rv = self.dispatch_request()
  File "/Library/Frameworks/Python.framework/Versions/3.5/lib/python3.5/site-packages/flask/app.py", line 1625, in dispatch_request
    return self.view_functions[rule.endpoint](**req.view_args)
  File "/Users/TheHD/Sites/teaching-api/api.py", line 44, in serveWeek
    'code': f.openFile(fp['path']),
  File "/Users/TheHD/Sites/teaching-api/model.py", line 22, in openFile
    return fo.read().encode('utf-8')
  File "/Library/Frameworks/Python.framework/Versions/3.5/lib/python3.5/encodings/ascii.py", line 26, in decode
    return codecs.ascii_decode(input, self.errors)[0]
UnicodeDecodeError: 'ascii' codec can't decode byte 0xe2 in position 579: ordinal not in range(128)
2017-11-29 16:25:01,101 - api - ERROR - Exception on /api/labs/week1 [GET]
Traceback (most recent call last):
  File "/Library/Frameworks/Python.framework/Versions/3.5/lib/python3.5/site-packages/flask/app.py", line 1988, in wsgi_app
    response = self.full_dispatch_request()
  File "/Library/Frameworks/Python.framework/Versions/3.5/lib/python3.5/site-packages/flask/app.py", line 1641, in full_dispatch_request
    rv = self.handle_user_exception(e)
  File "/Library/Frameworks/Python.framework/Versions/3.5/lib/python3.5/site-packages/flask/app.py", line 1544, in handle_user_exception
    reraise(exc_type, exc_value, tb)
  File "/Library/Frameworks/Python.framework/Versions/3.5/lib/python3.5/site-packages/flask/_compat.py", line 33, in reraise
    raise value
  File "/Library/Frameworks/Python.framework/Versions/3.5/lib/python3.5/site-packages/flask/app.py", line 1639, in full_dispatch_request
    rv = self.dispatch_request()
  File "/Library/Frameworks/Python.framework/Versions/3.5/lib/python3.5/site-packages/flask/app.py", line 1625, in dispatch_request
    return self.view_functions[rule.endpoint](**req.view_args)
  File "/Users/TheHD/Sites/teaching-api/api.py", line 44, in serveWeek
    'code': f.openFile(fp['path']),
  File "/Users/TheHD/Sites/teaching-api/model.py", line 22, in openFile
    return fo.read().encode('utf-8')
  File "/Library/Frameworks/Python.framework/Versions/3.5/lib/python3.5/encodings/ascii.py", line 26, in decode
    return codecs.ascii_decode(input, self.errors)[0]
UnicodeDecodeError: 'ascii' codec can't decode byte 0xe2 in position 579: ordinal not in range(128)
2017-11-29 16:25:10,167 - api - ERROR - Exception on /api/labs/week1 [GET]
Traceback (most recent call last):
  File "/Library/Frameworks/Python.framework/Versions/3.5/lib/python3.5/site-packages/flask/app.py", line 1988, in wsgi_app
    response = self.full_dispatch_request()
  File "/Library/Frameworks/Python.framework/Versions/3.5/lib/python3.5/site-packages/flask/app.py", line 1641, in full_dispatch_request
    rv = self.handle_user_exception(e)
  File "/Library/Frameworks/Python.framework/Versions/3.5/lib/python3.5/site-packages/flask/app.py", line 1544, in handle_user_exception
    reraise(exc_type, exc_value, tb)
  File "/Library/Frameworks/Python.framework/Versions/3.5/lib/python3.5/site-packages/flask/_compat.py", line 33, in reraise
    raise value
  File "/Library/Frameworks/Python.framework/Versions/3.5/lib/python3.5/site-packages/flask/app.py", line 1639, in full_dispatch_request
    rv = self.dispatch_request()
  File "/Library/Frameworks/Python.framework/Versions/3.5/lib/python3.5/site-packages/flask/app.py", line 1625, in dispatch_request
    return self.view_functions[rule.endpoint](**req.view_args)
  File "/Users/TheHD/Sites/teaching-api/api.py", line 44, in serveWeek
    'code': f.openFile(fp['path']),
  File "/Users/TheHD/Sites/teaching-api/model.py", line 22, in openFile
    return fo.read().encode('utf-8')
  File "/Library/Frameworks/Python.framework/Versions/3.5/lib/python3.5/encodings/ascii.py", line 26, in decode
    return codecs.ascii_decode(input, self.errors)[0]
UnicodeDecodeError: 'ascii' codec can't decode byte 0xe2 in position 579: ordinal not in range(128)
2017-11-30 14:31:17,829 - api - ERROR - Exception on /api/labs/week1/meta.json [GET]
Traceback (most recent call last):
  File "/Library/Frameworks/Python.framework/Versions/3.5/lib/python3.5/site-packages/flask/app.py", line 1988, in wsgi_app
    response = self.full_dispatch_request()
  File "/Library/Frameworks/Python.framework/Versions/3.5/lib/python3.5/site-packages/flask/app.py", line 1641, in full_dispatch_request
    rv = self.handle_user_exception(e)
  File "/Library/Frameworks/Python.framework/Versions/3.5/lib/python3.5/site-packages/flask/app.py", line 1544, in handle_user_exception
    reraise(exc_type, exc_value, tb)
  File "/Library/Frameworks/Python.framework/Versions/3.5/lib/python3.5/site-packages/flask/_compat.py", line 33, in reraise
    raise value
  File "/Library/Frameworks/Python.framework/Versions/3.5/lib/python3.5/site-packages/flask/app.py", line 1639, in full_dispatch_request
    rv = self.dispatch_request()
  File "/Library/Frameworks/Python.framework/Versions/3.5/lib/python3.5/site-packages/flask/app.py", line 1625, in dispatch_request
    return self.view_functions[rule.endpoint](**req.view_args)
  File "/Users/TheHD/Sites/teaching-api/api.py", line 32, in sendMeta
    return send_from_directory('labs/', week, 'meta.json')
NameError: name 'send_from_directory' is not defined
2017-11-30 14:32:20,964 - api - ERROR - Exception on /api/labs/week1/meta.json [GET]
Traceback (most recent call last):
  File "/Library/Frameworks/Python.framework/Versions/3.5/lib/python3.5/site-packages/flask/app.py", line 1988, in wsgi_app
    response = self.full_dispatch_request()
  File "/Library/Frameworks/Python.framework/Versions/3.5/lib/python3.5/site-packages/flask/app.py", line 1641, in full_dispatch_request
    rv = self.handle_user_exception(e)
  File "/Library/Frameworks/Python.framework/Versions/3.5/lib/python3.5/site-packages/flask/app.py", line 1544, in handle_user_exception
    reraise(exc_type, exc_value, tb)
  File "/Library/Frameworks/Python.framework/Versions/3.5/lib/python3.5/site-packages/flask/_compat.py", line 33, in reraise
    raise value
  File "/Library/Frameworks/Python.framework/Versions/3.5/lib/python3.5/site-packages/flask/app.py", line 1639, in full_dispatch_request
    rv = self.dispatch_request()
  File "/Library/Frameworks/Python.framework/Versions/3.5/lib/python3.5/site-packages/flask/app.py", line 1625, in dispatch_request
    return self.view_functions[rule.endpoint](**req.view_args)
  File "/Users/TheHD/Sites/teaching-api/api.py", line 32, in sendMeta
    return send_from_directory('labs/', week, 'meta.json')
TypeError: send_from_directory() takes 2 positional arguments but 3 were given
2017-11-30 14:32:22,001 - api - ERROR - Exception on /api/labs/week1/meta.json [GET]
Traceback (most recent call last):
  File "/Library/Frameworks/Python.framework/Versions/3.5/lib/python3.5/site-packages/flask/app.py", line 1988, in wsgi_app
    response = self.full_dispatch_request()
  File "/Library/Frameworks/Python.framework/Versions/3.5/lib/python3.5/site-packages/flask/app.py", line 1641, in full_dispatch_request
    rv = self.handle_user_exception(e)
  File "/Library/Frameworks/Python.framework/Versions/3.5/lib/python3.5/site-packages/flask/app.py", line 1544, in handle_user_exception
    reraise(exc_type, exc_value, tb)
  File "/Library/Frameworks/Python.framework/Versions/3.5/lib/python3.5/site-packages/flask/_compat.py", line 33, in reraise
    raise value
  File "/Library/Frameworks/Python.framework/Versions/3.5/lib/python3.5/site-packages/flask/app.py", line 1639, in full_dispatch_request
    rv = self.dispatch_request()
  File "/Library/Frameworks/Python.framework/Versions/3.5/lib/python3.5/site-packages/flask/app.py", line 1625, in dispatch_request
    return self.view_functions[rule.endpoint](**req.view_args)
  File "/Users/TheHD/Sites/teaching-api/api.py", line 32, in sendMeta
    return send_from_directory('labs/', week, 'meta.json')
TypeError: send_from_directory() takes 2 positional arguments but 3 were given
2017-11-30 14:32:48,148 - api - ERROR - Exception on /api/labs/week1/meta.json [GET]
Traceback (most recent call last):
  File "/Library/Frameworks/Python.framework/Versions/3.5/lib/python3.5/site-packages/flask/app.py", line 1988, in wsgi_app
    response = self.full_dispatch_request()
  File "/Library/Frameworks/Python.framework/Versions/3.5/lib/python3.5/site-packages/flask/app.py", line 1641, in full_dispatch_request
    rv = self.handle_user_exception(e)
  File "/Library/Frameworks/Python.framework/Versions/3.5/lib/python3.5/site-packages/flask/app.py", line 1544, in handle_user_exception
    reraise(exc_type, exc_value, tb)
  File "/Library/Frameworks/Python.framework/Versions/3.5/lib/python3.5/site-packages/flask/_compat.py", line 33, in reraise
    raise value
  File "/Library/Frameworks/Python.framework/Versions/3.5/lib/python3.5/site-packages/flask/app.py", line 1639, in full_dispatch_request
    rv = self.dispatch_request()
  File "/Library/Frameworks/Python.framework/Versions/3.5/lib/python3.5/site-packages/flask/app.py", line 1625, in dispatch_request
    return self.view_functions[rule.endpoint](**req.view_args)
  File "/Users/TheHD/Sites/teaching-api/api.py", line 32, in sendMeta
    return send_from_directory('labs/', week, 'meta.json')
TypeError: send_from_directory() takes 2 positional arguments but 3 were given
2017-11-30 18:54:43,199 - api - ERROR - Exception on /api/labs [GET]
Traceback (most recent call last):
  File "/Library/Frameworks/Python.framework/Versions/3.5/lib/python3.5/site-packages/flask/app.py", line 1988, in wsgi_app
    response = self.full_dispatch_request()
  File "/Library/Frameworks/Python.framework/Versions/3.5/lib/python3.5/site-packages/flask/app.py", line 1641, in full_dispatch_request
    rv = self.handle_user_exception(e)
  File "/Library/Frameworks/Python.framework/Versions/3.5/lib/python3.5/site-packages/flask/app.py", line 1544, in handle_user_exception
    reraise(exc_type, exc_value, tb)
  File "/Library/Frameworks/Python.framework/Versions/3.5/lib/python3.5/site-packages/flask/_compat.py", line 33, in reraise
    raise value
  File "/Library/Frameworks/Python.framework/Versions/3.5/lib/python3.5/site-packages/flask/app.py", line 1639, in full_dispatch_request
    rv = self.dispatch_request()
  File "/Library/Frameworks/Python.framework/Versions/3.5/lib/python3.5/site-packages/flask/app.py", line 1625, in dispatch_request
    return self.view_functions[rule.endpoint](**req.view_args)
  File "/Users/TheHD/Sites/teaching-api/api.py", line 38, in serveLabs
    return(jsonify(f.sendProperNames()))
  File "/Users/TheHD/Sites/teaching-api/model.py", line 25, in sendProperNames
    return [{ 'path': i.path, 'name': "Week {}".format(i.name[4:]) } for i in self.files]
  File "/Users/TheHD/Sites/teaching-api/model.py", line 25, in <listcomp>
    return [{ 'path': i.path, 'name': "Week {}".format(i.name[4:]) } for i in self.files]
AttributeError: 'dict' object has no attribute 'path'
2017-11-30 18:54:52,686 - api - ERROR - Exception on /api/labs [GET]
Traceback (most recent call last):
  File "/Library/Frameworks/Python.framework/Versions/3.5/lib/python3.5/site-packages/flask/app.py", line 1988, in wsgi_app
    response = self.full_dispatch_request()
  File "/Library/Frameworks/Python.framework/Versions/3.5/lib/python3.5/site-packages/flask/app.py", line 1641, in full_dispatch_request
    rv = self.handle_user_exception(e)
  File "/Library/Frameworks/Python.framework/Versions/3.5/lib/python3.5/site-packages/flask/app.py", line 1544, in handle_user_exception
    reraise(exc_type, exc_value, tb)
  File "/Library/Frameworks/Python.framework/Versions/3.5/lib/python3.5/site-packages/flask/_compat.py", line 33, in reraise
    raise value
  File "/Library/Frameworks/Python.framework/Versions/3.5/lib/python3.5/site-packages/flask/app.py", line 1639, in full_dispatch_request
    rv = self.dispatch_request()
  File "/Library/Frameworks/Python.framework/Versions/3.5/lib/python3.5/site-packages/flask/app.py", line 1625, in dispatch_request
    return self.view_functions[rule.endpoint](**req.view_args)
  File "/Users/TheHD/Sites/teaching-api/api.py", line 38, in serveLabs
    return(jsonify(f.sendProperNames()))
  File "/Users/TheHD/Sites/teaching-api/model.py", line 25, in sendProperNames
    return [{ 'path': i.path, 'name': "Week {}".format(i.name[4:]) } for i in self.files]
  File "/Users/TheHD/Sites/teaching-api/model.py", line 25, in <listcomp>
    return [{ 'path': i.path, 'name': "Week {}".format(i.name[4:]) } for i in self.files]
AttributeError: 'dict' object has no attribute 'path'
2017-11-30 19:04:23,918 - api - ERROR - Exception on /api/labs/labs [GET]
Traceback (most recent call last):
  File "/Library/Frameworks/Python.framework/Versions/3.5/lib/python3.5/site-packages/flask/app.py", line 1988, in wsgi_app
    response = self.full_dispatch_request()
  File "/Library/Frameworks/Python.framework/Versions/3.5/lib/python3.5/site-packages/flask/app.py", line 1641, in full_dispatch_request
    rv = self.handle_user_exception(e)
  File "/Library/Frameworks/Python.framework/Versions/3.5/lib/python3.5/site-packages/flask/app.py", line 1544, in handle_user_exception
    reraise(exc_type, exc_value, tb)
  File "/Library/Frameworks/Python.framework/Versions/3.5/lib/python3.5/site-packages/flask/_compat.py", line 33, in reraise
    raise value
  File "/Library/Frameworks/Python.framework/Versions/3.5/lib/python3.5/site-packages/flask/app.py", line 1639, in full_dispatch_request
    rv = self.dispatch_request()
  File "/Library/Frameworks/Python.framework/Versions/3.5/lib/python3.5/site-packages/flask/app.py", line 1625, in dispatch_request
    return self.view_functions[rule.endpoint](**req.view_args)
  File "/Users/TheHD/Sites/teaching-api/api.py", line 42, in serveWeek
    f = FileParser('labs/{}'.format(week))
  File "/Users/TheHD/Sites/teaching-api/model.py", line 11, in __init__
    self._populate()
  File "/Users/TheHD/Sites/teaching-api/model.py", line 17, in _populate
    for i in os.listdir(os.path.join(os.path.dirname(__file__), self.path))
FileNotFoundError: [Errno 2] No such file or directory: '/Users/TheHD/Sites/teaching-api/labs/labs'
